Workbook
Name Acciones_Educación_vial: #REF!
Name Acciones_Educación_vial: #REF!
Name Acciones_Educación_vial: #REF!
Name Acciones_Educación_vial: #REF!
Name Acciones_Educación_vial: #REF!
Name EDUVIAL_2024: #REF!
Name EDUVIAL_2024: #REF!
Name EDUVIAL_2024: #REF!
Name EDUVIAL_2024: EDUVIAL_2023[#All]
Name IITRIM: SEGUIMIENTO!$A$1:$V$307
Name IITRIM: #REF!

Sheet SEGUIMIENTO
A1: FECHA DE LA ACTIVIDAD (DÍA-MES-AÑO) | B1: MES | C1: ÁREA DE EDUCACIÓN VIAL | D1: PÚBLICOS | E1: TIPO DE INTERVENCIÓN | F1: RESPONSABLE | G1: DESCRIPCIÓN DE ACTIVIDAD (Escriba brevemente la actividad realizada) | H1: INSTITUCIÓN O EMPRESA | I1: PERSONA DE CONTACTO O BENEFICIARIO | J1: HOMBRE | K1: MUJER | L1: TOTAL SEXO | M1: PRIMERA INFANCIA (Hasta 5 años) | N1: INFANCIA (6 a 11 años) | O1: ADOLESCENCIA (12 años a 17 años) | P1: ADULTOS-JÓVENES (18 años a 28 años) | Q1: ADULTOS (29 años a 60 años) | R1: PERSONAS MAYORES ( Mayores de 60 años) | S1: TOTAL RANGOS | T1: TOTAL GENERAL (no modificar) | U1: ZONA | V1: BARRIO | W1: GEOREFERENCIACIÓN | X1: TOTAL GENERAL (no modificar)2 | Y1: TOTAL GENERAL (no modificar)3
A2: 45672 | B2: ENE | C2: Acciones Por La Vida - ANSV | D2: Motociclistas | E2: Acciones por la vida para motociclistas ANSV | F2: Juan Carlos Caicedo | G2: Desarrollar actividades pedagógicas y artísticas en vía para mitigar conductas de riesgo que están asociadas a los siniestros viales | H2: Agencia Nacional de Seguridad Vial | I2: Andrés Cristancho | J2: 4 | K2: 2 | L2: =EDUVIAL_2023[[#This Row],[HOMBRE]]+EDUVIAL_2023[[#This Row],[MUJER]] -> 6 | M2: 0 | N2: 0 | O2: 0 | P2: 0 | Q2: 4 | R2: 2 | S2: =EDUVIAL_2023[[#This Row],[PRIMERA INFANCIA (Hasta 5 años)]]+EDUVIAL_2023[[#This Row],[INFANCIA (6 a 11 años)]]+EDUVIAL_2023[[#This Row],[ADOLESCENCIA (12 años a 17 años)]]+EDUVIAL_2023[[#This Row],[ADULTOS-JÓVENES (18 años a 28 años)]]+EDUVIAL_2023[[#This Row],[PERSONAS MAYORES ( Mayores de 60 años)]]+EDUVIAL_2023[[#This Row],[ADULTOS (29 años a 60 años)]] -> 6 | T2: =EDUVIAL_2023[[#This Row],[TOTAL SEXO]] -> 6 | U2: Zona 9 | V2: Centro | W2: 6.169773013301722, -75.58747462568526 | X2: =EXACT(EDUVIAL_2023[[#This Row],[TOTAL SEXO]],EDUVIAL_2023[[#This Row],[TOTAL RANGOS]]) -> TRUE
A3: 45678 | B3: ENE | C3: Acciones Por La Vida - ANSV | D3: Motociclistas | E3: Acciones por la vida para motociclistas ANSV | F3: Juan Carlos Caicedo | G3: Desarrollar actividades pedagógicas y artísticas en vía para mitigar conductas de riesgo que están asociadas a los siniestros viales | H3: Agencia Nacional de Seguridad Vial | I3: Andrés Cristancho | J3: 43 | K3: 11 | L3: =EDUVIAL_2023[[#This Row],[HOMBRE]]+EDUVIAL_2023[[#This Row],[MUJER]] -> 54 | M3: 0 | N3: 0 | O3: 4 | P3: 10 | Q3: 34 | R3: 6 | S3: =EDUVIAL_2023[[#This Row],[PRIMERA INFANCIA (Hasta 5 años)]]+EDUVIAL_2023[[#This Row],[INFANCIA (6 a 11 años)]]+EDUVIAL_2023[[#This Row],[ADOLESCENCIA (12 años a 17 años)]]+EDUVIAL_2023[[#This Row],[ADULTOS-JÓVENES (18 años a 28 años)]]+EDUVIAL_2023[[#This Row],[PERSONAS MAYORES ( Mayores de 60 años)]]+EDUVIAL_2023[[#This Row],[ADULTOS (29 años a 60 años)]] -> 54 | T3: =EDUVIAL_2023[[#This Row],[TOTAL SEXO]] -> 54 | U3: Zona 9 | V3: Centro | W3: 6.169773013301722, -75.58747462568526 | X3: =EXACT(EDUVIAL_2023[[#This Row],[TOTAL SEXO]],EDUVIAL_2023[[#This Row],[TOTAL RANGOS]]) -> TRUE
A4: 45679 | B4: ENE | C4: Experiencias ciudadanas en movilidad sostenible y segura | D4: Conductores sancionados por embriaguez | E4: Orientación y seguimiento a labor comunitaria | F4: Juan Carlos Caicedo | G4: Sensibilización en prevención de la conducción bajo los efectos del alcohol o sustancias psicoactivas. | H4: Secretaría de Movilidad | I4: Jorge Wilson Osorio | J4: 1 | K4: 0 | L4: =EDUVIAL_2023[[#This Row],[HOMBRE]]+EDUVIAL_2023[[#This Row],[MUJER]] -> 1 | M4: 0 | N4: 0 | O4: 0 | P4: 0 | Q4: 1 | R4: 0 | S4: =EDUVIAL_2023[[#This Row],[PRIMERA INFANCIA (Hasta 5 años)]]+EDUVIAL_2023[[#This Row],[INFANCIA (6 a 11 años)]]+EDUVIAL_2023[[#This Row],[ADOLESCENCIA (12 años a 17 años)]]+EDUVIAL_2023[[#This Row],[ADULTOS-JÓVENES (18 años a 28 años)]]+EDUVIAL_2023[[#This Row],[PERSONAS MAYORES ( Mayores de 60 años)]]+EDUVIAL_2023[[#This Row],[ADULTOS (29 años a 60 años)]] -> 1 | T4: =EDUVIAL_2023[[#This Row],[TOTAL SEXO]] -> 1 | U4: Zona 9 | V4: Centro | W4: 6.168450558868997, -75.5896412723252 | X4: =EXACT(EDUVIAL_2023[[#This Row],[TOTAL SEXO]],EDUVIAL_2023[[#This Row],[TOTAL RANGOS]]) -> TRUE
A5: 45680 | B5: ENE | C5: Acciones Por La Vida - ANSV | D5: Motociclistas | E5: Acciones por la vida para motociclistas ANSV | F5: Juan Carlos Caicedo | G5: Desarrollar actividades pedagógicas y artísticas en vía para mitigar conductas de riesgo que están asociadas a los siniestros viales | H5: Agencia Nacional de Seguridad Vial | I5: Andrés Cristancho | J5: 21 | K5: 9 | L5: =EDUVIAL_2023[[#This Row],[HOMBRE]]+EDUVIAL_2023[[#This Row],[MUJER]] -> 30 | M5: 0 | N5: 0 | O5: 1 | P5: 10 | Q5: 19 | R5: 0 | S5: =EDUVIAL_2023[[#This Row],[PRIMERA INFANCIA (Hasta 5 años)]]+EDUVIAL_2023[[#This Row],[INFANCIA (6 a 11 años)]]+EDUVIAL_2023[[#This Row],[ADOLESCENCIA (12 años a 17 años)]]+EDUVIAL_2023[[#This Row],[ADULTOS-JÓVENES (18 años a 28 años)]]+EDUVIAL_2023[[#This Row],[PERSONAS MAYORES ( Mayores de 60 años)]]+EDUVIAL_2023[[#This Row],[ADULTOS (29 años a 60 años)]] -> 30 | T5: =EDUVIAL_2023[[#This Row],[TOTAL SEXO]] -> 30 | U5: Zona 9 | V5: Centro | W5: 6.169773013301722, -75.58747462568526 | X5: =EXACT(EDUVIAL_2023[[#This Row],[TOTAL SEXO]],EDUVIAL_2023[[#This Row],[TOTAL RANGOS]]) -> TRUE
A6: 45684 | B6: ENE | C6: Experiencias ciudadanas en movilidad sostenible y segura | D6: Conductores sancionados por embriaguez | E6: Orientación y seguimiento a labor comunitaria | F6: Jairo Gaviria | G6: Sensibilización en prevención de la conducción bajo los efectos del alcohol o sustancias psicoactivas. | H6: Secretaría de Movilidad | I6: Emiro Jose Osorio | J6: 1 | K6: 0 | L6: =EDUVIAL_2023[[#This Row],[HOMBRE]]+EDUVIAL_2023[[#This Row],[MUJER]] -> 1 | M6: 0 | N6: 0 | O6: 0 | P6: 0 | Q6: 1 | R6: 0 | S6: =EDUVIAL_2023[[#This Row],[PRIMERA INFANCIA (Hasta 5 años)]]+EDUVIAL_2023[[#This Row],[INFANCIA (6 a 11 años)]]+EDUVIAL_2023[[#This Row],[ADOLESCENCIA (12 años a 17 años)]]+EDUVIAL_2023[[#This Row],[ADULTOS-JÓVENES (18 años a 28 años)]]+EDUVIAL_2023[[#This Row],[PERSONAS MAYORES ( Mayores de 60 años)]]+EDUVIAL_2023[[#This Row],[ADULTOS (29 años a 60 años)]] -> 1 | T6: =EDUVIAL_2023[[#This Row],[TOTAL SEXO]] -> 1 | U6: Zona 9 | V6: Centro | W6: 6.169773013301722, -75.58747462568526 | X6: =EXACT(EDUVIAL_2023[[#This Row],[TOTAL SEXO]],EDUVIAL_2023[[#This Row],[TOTAL RANGOS]]) -> TRUE
A7: 45688 | B7: ENE | C7: Experiencias ciudadanas en movilidad sostenible y segura | D7: Conductores sancionados por embriaguez | E7: Orientación y seguimiento a labor comunitaria | F7: Jairo Gaviria | G7: Sensibilización en prevención de la conducción bajo los efectos del alcohol o sustancias psicoactivas. | H7: Secretaría de Movilidad | I7: Jairo Camacho Lara | J7: 1 | K7: 0 | L7: =EDUVIAL_2023[[#This Row],[HOMBRE]]+EDUVIAL_2023[[#This Row],[MUJER]] -> 1 | M7: 0 | N7: 0 | O7: 0 | P7: 0 | Q7: 0 | R7: 1 | S7: =EDUVIAL_2023[[#This Row],[PRIMERA INFANCIA (Hasta 5 años)]]+EDUVIAL_2023[[#This Row],[INFANCIA (6 a 11 años)]]+EDUVIAL_2023[[#This Row],[ADOLESCENCIA (12 años a 17 años)]]+EDUVIAL_2023[[#This Row],[ADULTOS-JÓVENES (18 años a 28 años)]]+EDUVIAL_2023[[#This Row],[PERSONAS MAYORES ( Mayores de 60 años)]]+EDUVIAL_2023[[#This Row],[ADULTOS (29 años a 60 años)]] -> 1 | T7: =EDUVIAL_2023[[#This Row],[TOTAL SEXO]] -> 1 | U7: Zona 9 | V7: Centro | W7: 6.169773013301722, -75.58747462568526 | X7: =EXACT(EDUVIAL_2023[[#This Row],[TOTAL SEXO]],EDUVIAL_2023[[#This Row],[TOTAL RANGOS]]) -> TRUE
A8: 45698 | B8: FEB | C8: Experiencias ciudadanas en movilidad sostenible y segura | D8: Conductores sancionados por embriaguez | E8: Orientación y seguimiento a labor comunitaria | F8: Jairo Gaviria | G8: Sensibilización en prevención de la conducción bajo los efectos del alcohol o sustancias psicoactivas. | H8: Secretaría de Movilidad | I8: Diego Alexander Renso | J8: 1 | K8: 0 | L8: =EDUVIAL_2023[[#This Row],[HOMBRE]]+EDUVIAL_2023[[#This Row],[MUJER]] -> 1 | M8: 0 | N8: 0 | O8: 0 | P8: 0 | Q8: 1 | R8: 0 | S8: =EDUVIAL_2023[[#This Row],[PRIMERA INFANCIA (Hasta 5 años)]]+EDUVIAL_2023[[#This Row],[INFANCIA (6 a 11 años)]]+EDUVIAL_2023[[#This Row],[ADOLESCENCIA (12 años a 17 años)]]+EDUVIAL_2023[[#This Row],[ADULTOS-JÓVENES (18 años a 28 años)]]+EDUVIAL_2023[[#This Row],[PERSONAS MAYORES ( Mayores de 60 años)]]+EDUVIAL_2023[[#This Row],[ADULTOS (29 años a 60 años)]] -> 1 | T8: =EDUVIAL_2023[[#This Row],[TOTAL SEXO]] -> 1 | U8: Zona 9 | V8: Centro | W8: 6.169773013301722, -75.58747462568526 | X8: =EXACT(EDUVIAL_2023[[#This Row],[TOTAL SEXO]],EDUVIAL_2023[[#This Row],[TOTAL RANGOS]]) -> TRUE
A9: 45698 | B9: FEB | C9: Experiencias ciudadanas en movilidad sostenible y segura | D9: Conductores sancionados por embriaguez | E9: Orientación y seguimiento a labor comunitaria | F9: Jairo Gaviria | G9: Sensibilización en prevención de la conducción bajo los efectos del alcohol o sustancias psicoactivas. | H9: Secretaría de Movilidad | I9: Juan David Hurtado | J9: 1 | K9: 0 | L9: =EDUVIAL_2023[[#This Row],[HOMBRE]]+EDUVIAL_2023[[#This Row],[MUJER]] -> 1 | M9: 0 | N9: 0 | O9: 0 | P9: 0 | Q9: 1 | R9: 0 | S9: =EDUVIAL_2023[[#This Row],[PRIMERA INFANCIA (Hasta 5 años)]]+EDUVIAL_2023[[#This Row],[INFANCIA (6 a 11 años)]]+EDUVIAL_2023[[#This Row],[ADOLESCENCIA (12 años a 17 años)]]+EDUVIAL_2023[[#This Row],[ADULTOS-JÓVENES (18 años a 28 años)]]+EDUVIAL_2023[[#This Row],[PERSONAS MAYORES ( Mayores de 60 años)]]+EDUVIAL_2023[[#This Row],[ADULTOS (29 años a 60 años)]] -> 1 | T9: =EDUVIAL_2023[[#This Row],[TOTAL SEXO]] -> 1 | U9: Zona 9 | V9: Centro | W9: 6.169773013301722, -75.58747462568526 | X9: =EXACT(EDUVIAL_2023[[#This Row],[TOTAL SEXO]],EDUVIAL_2023[[#This Row],[TOTAL RANGOS]]) -> TRUE
A10: 45698 | B10: FEB | C10: Educación vial en empresas | D10: Colaboradores de las diferentes dependencias de la Alcaldía | E10: Formación para el fortalecimiento de conocimientos, hábitos y comportamientos seguros | F10: Jairo Gaviria | G10: Recomendaciones de seguridad vial como conductores y acompañantes de motocicleta | H10: Secretaria de Gobierno | I10: Geovanny Perez | J10: 20 | K10: 4 | L10: =EDUVIAL_2023[[#This Row],[HOMBRE]]+EDUVIAL_2023[[#This Row],[MUJER]] -> 24 | M10: 0 | N10: 0 | O10: 0 | P10: 0 | Q10: 24 | R10: 0 | S10: =EDUVIAL_2023[[#This Row],[PRIMERA INFANCIA (Hasta 5 años)]]+EDUVIAL_2023[[#This Row],[INFANCIA (6 a 11 años)]]+EDUVIAL_2023[[#This Row],[ADOLESCENCIA (12 años a 17 años)]]+EDUVIAL_2023[[#This Row],[ADULTOS-JÓVENES (18 años a 28 años)]]+EDUVIAL_2023[[#This Row],[PERSONAS MAYORES ( Mayores de 60 años)]]+EDUVIAL_2023[[#This Row],[ADULTOS (29 años a 60 años)]] -> 24 | T10: =EDUVIAL_2023[[#This Row],[TOTAL SEXO]] -> 24 | U10: Zona 2 | V10: San Marcos | W10: 6.173125983893078, -75.58883704052495 | X10: =EXACT(EDUVIAL_2023[[#This Row],[TOTAL SEXO]],EDUVIAL_2023[[#This Row],[TOTAL RANGOS]]) -> TRUE
A11: 45699 | B11: FEB | C11: Educación vial en empresas | D11: Colaboradores de las diferentes dependencias de la Alcaldía | E11: Formación para el fortalecimiento de conocimientos, hábitos y comportamientos seguros | F11: Jairo Gaviria | G11: Reunion de planeacion de las diferentes intervenciones en educacion y seguridad vial para Amigos del Barrio y cuena | H11: Enviaseo | I11: Juan David Carmona | J11: 1 | K11: 0 | L11: =EDUVIAL_2023[[#This Row],[HOMBRE]]+EDUVIAL_2023[[#This Row],[MUJER]] -> 1 | M11: 0 | N11: 0 | O11: 0 | P11: 0 | Q11: 1 | R11: 0 | S11: =EDUVIAL_2023[[#This Row],[PRIMERA INFANCIA (Hasta 5 años)]]+EDUVIAL_2023[[#This Row],[INFANCIA (6 a 11 años)]]+EDUVIAL_2023[[#This Row],[ADOLESCENCIA (12 años a 17 años)]]+EDUVIAL_2023[[#This Row],[ADULTOS-JÓVENES (18 años a 28 años)]]+EDUVIAL_2023[[#This Row],[PERSONAS MAYORES ( Mayores de 60 años)]]+EDUVIAL_2023[[#This Row],[ADULTOS (29 años a 60 años)]] -> 1 | T11: =EDUVIAL_2023[[#This Row],[TOTAL SEXO]] -> 1 | U11: Zona 9 | V11: Centro | W11: 6.169773013301722, -75.58747462568526 | X11: =EXACT(EDUVIAL_2023[[#This Row],[TOTAL SEXO]],EDUVIAL_2023[[#This Row],[TOTAL RANGOS]]) -> TRUE
A12: 45700 | B12: FEB | C12: Experiencias ciudadanas en movilidad sostenible y segura | D12: Colaboradores de las diferentes dependencias de la Alcaldía | E12: Enviciescuela. Actividad experiencial en bicicleta | F12: Jairo Gaviria | G12: Reunion de planeacion de las actividades del programa de Enviciescuela con personal del INDER | H12: Secretaría de Movilidad | I12: Juan Pablo zorrilla | J12: 2 | K12: 0 | L12: =EDUVIAL_2023[[#This Row],[HOMBRE]]+EDUVIAL_2023[[#This Row],[MUJER]] -> 2 | M12: 0 | N12: 0 | O12: 0 | P12: 0 | Q12: 2 | R12: 0 | S12: =EDUVIAL_2023[[#This Row],[PRIMERA INFANCIA (Hasta 5 años)]]+EDUVIAL_2023[[#This Row],[INFANCIA (6 a 11 años)]]+EDUVIAL_2023[[#This Row],[ADOLESCENCIA (12 años a 17 años)]]+EDUVIAL_2023[[#This Row],[ADULTOS-JÓVENES (18 años a 28 años)]]+EDUVIAL_2023[[#This Row],[PERSONAS MAYORES ( Mayores de 60 años)]]+EDUVIAL_2023[[#This Row],[ADULTOS (29 años a 60 años)]] -> 2 | T12: =EDUVIAL_2023[[#This Row],[TOTAL SEXO]] -> 2 | U12: Zona 1 | V12: Las Vegas | W12: 6.165622783551734, -75.5992929118132 | X12: =EXACT(EDUVIAL_2023[[#This Row],[TOTAL SEXO]],EDUVIAL_2023[[#This Row],[TOTAL RANGOS]]) -> TRUE
A13: 45700 | B13: FEB | C13: Educación vial en instituciones educativas | D13: Docentes de primaria instituciones educativas | E13: Reunión de planeación para actividades | F13: Jairo Gaviria | G13: Reunion de planeacion de las actividades de educacion vial con docentes,padrs de familia y alumnos | H13: I.E JOSE MANUEL RESTREPO VELEZ - SEDE FERNANDO GONZALEZ | I13: Gloria Rojas | J13: 0 | K13: 1 | L13: =EDUVIAL_2023[[#This Row],[HOMBRE]]+EDUVIAL_2023[[#This Row],[MUJER]] -> 1 | M13: 0 | N13: 0 | O13: 0 | P13: 0 | Q13: 1 | R13: 0 | S13: =EDUVIAL_2023[[#This Row],[PRIMERA INFANCIA (Hasta 5 años)]]+EDUVIAL_2023[[#This Row],[INFANCIA (6 a 11 años)]]+EDUVIAL_2023[[#This Row],[ADOLESCENCIA (12 años a 17 años)]]+EDUVIAL_2023[[#This Row],[ADULTOS-JÓVENES (18 años a 28 años)]]+EDUVIAL_2023[[#This Row],[PERSONAS MAYORES ( Mayores de 60 años)]]+EDUVIAL_2023[[#This Row],[ADULTOS (29 años a 60 años)]] -> 1 | T13: =EDUVIAL_2023[[#This Row],[TOTAL SEXO]] -> 1 | U13: Zona 8 | V13: Alcalà | W13: =VLOOKUP(EDUVIAL_2023[[#This Row],[INSTITUCIÓN O EMPRESA]],LISTAS!$J$1:$M$81,2,0) -> 6.167664, -75.586311 | X13: =EXACT(EDUVIAL_2023[[#This Row],[TOTAL SEXO]],EDUVIAL_2023[[#This Row],[TOTAL RANGOS]]) -> TRUE
A14: 45701 | B14: FEB | C14: Educación vial en instituciones educativas | D14: Docentes de primaria instituciones educativas | E14: Reunión de planeación para actividades | F14: Jairo Gaviria | G14: Reunion de planeacion de las actividades de educacion vial con docentes,padrs de familia y alumnos | H14: I.E LA PAZ | I14: Wilmar Florez | J14: 1 | K14: 0 | L14: =EDUVIAL_2023[[#This Row],[HOMBRE]]+EDUVIAL_2023[[#This Row],[MUJER]] -> 1 | M14: 0 | N14: 0 | O14: 0 | P14: 0 | Q14: 1 | R14: 0 | S14: =EDUVIAL_2023[[#This Row],[PRIMERA INFANCIA (Hasta 5 años)]]+EDUVIAL_2023[[#This Row],[INFANCIA (6 a 11 años)]]+EDUVIAL_2023[[#This Row],[ADOLESCENCIA (12 años a 17 años)]]+EDUVIAL_2023[[#This Row],[ADULTOS-JÓVENES (18 años a 28 años)]]+EDUVIAL_2023[[#This Row],[PERSONAS MAYORES ( Mayores de 60 años)]]+EDUVIAL_2023[[#This Row],[ADULTOS (29 años a 60 años)]] -> 1 | T14: =EDUVIAL_2023[[#This Row],[TOTAL SEXO]] -> 1 | U14: =VLOOKUP(EDUVIAL_2023[[#This Row],[INSTITUCIÓN O EMPRESA]],LISTAS!$J$1:$M$81,3,0) -> Zona 7 | V14: =VLOOKUP(EDUVIAL_2023[[#This Row],[INSTITUCIÓN O EMPRESA]],LISTAS!$J$1:$M$81,4,0) -> La Paz | W14: =VLOOKUP(EDUVIAL_2023[[#This Row],[INSTITUCIÓN O EMPRESA]],LISTAS!$J$1:$M$81,2,0) -> 6.162272, -75.594035 | X14: =EXACT(EDUVIAL_2023[[#This Row],[TOTAL SEXO]],EDUVIAL_2023[[#This Row],[TOTAL RANGOS]]) -> TRUE
A15: 45701 | B15: FEB | C15: Educación vial en empresas | D15: Agente de Transito | E15: Sensibilizaciones en educación vial | F15: Daniel Ríos | G15: Recomendaciones de seguridad vial como conductores y acompañantes de motocicleta. | H15: Secretaría de Movilidad | I15: Alejandro Barco | J15: 1 | K15: 0 | L15: =EDUVIAL_2023[[#This Row],[HOMBRE]]+EDUVIAL_2023[[#This Row],[MUJER]] -> 1 | M15: 0 | N15: 0 | O15: 0 | P15: 0 | Q15: 1 | R15: 0 | S15: =EDUVIAL_2023[[#This Row],[PRIMERA INFANCIA (Hasta 5 años)]]+EDUVIAL_2023[[#This Row],[INFANCIA (6 a 11 años)]]+EDUVIAL_2023[[#This Row],[ADOLESCENCIA (12 años a 17 años)]]+EDUVIAL_2023[[#This Row],[ADULTOS-JÓVENES (18 años a 28 años)]]+EDUVIAL_2023[[#This Row],[PERSONAS MAYORES ( Mayores de 60 años)]]+EDUVIAL_2023[[#This Row],[ADULTOS (29 años a 60 años)]] -> 1 | T15: =EDUVIAL_2023[[#This Row],[TOTAL SEXO]] -> 1 | U15: Zona 9 | V15: Centro | W15: 6.169773013301722, -75.58747462568526 | X15: =EXACT(EDUVIAL_2023[[#This Row],[TOTAL SEXO]],EDUVIAL_2023[[#This Row],[TOTAL RANGOS]]) -> TRUE
A16: 45701 | B16: FEB | C16: Educación vial en empresas | D16: Agente de Transito | E16: Sensibilizaciones en educación vial | F16: Daniel Ríos | G16: Recomendaciones de seguridad vial como conductores y acompañantes de motocicleta. | H16: Secretaría de Movilidad | I16: Brenda Cepeda | J16: 0 | K16: 1 | L16: =EDUVIAL_2023[[#This Row],[HOMBRE]]+EDUVIAL_2023[[#This Row],[MUJER]] -> 1 | M16: 0 | N16: 0 | O16: 0 | P16: 0 | Q16: 1 | R16: 0 | S16: =EDUVIAL_2023[[#This Row],[PRIMERA INFANCIA (Hasta 5 años)]]+EDUVIAL_2023[[#This Row],[INFANCIA (6 a 11 años)]]+EDUVIAL_2023[[#This Row],[ADOLESCENCIA (12 años a 17 años)]]+EDUVIAL_2023[[#This Row],[ADULTOS-JÓVENES (18 años a 28 años)]]+EDUVIAL_2023[[#This Row],[PERSONAS MAYORES ( Mayores de 60 años)]]+EDUVIAL_2023[[#This Row],[ADULTOS (29 años a 60 años)]] -> 1 | T16: =EDUVIAL_2023[[#This Row],[TOTAL SEXO]] -> 1 | U16: Zona 9 | V16: Centro | W16: 6.169773013301722, -75.58747462568526 | X16: =EXACT(EDUVIAL_2023[[#This Row],[TOTAL SEXO]],EDUVIAL_2023[[#This Row],[TOTAL RANGOS]]) -> TRUE
A17: 45705 | B17: FEB | C17: Educación vial en instituciones educativas | D17: Docentes de primaria instituciones educativas | E17: Formación para el fortalecimiento de conocimientos, hábitos y comportamientos seguros | F17: Jairo Gaviria | G17: Taller transversalidad de las areas del conocimiento con movilidad | H17: I.E COMERCIAL DE ENVIGADO - SEDE PIO XII | I17: Samira Fonseca | J17: 1 | K17: 10 | L17: =EDUVIAL_2023[[#This Row],[HOMBRE]]+EDUVIAL_2023[[#This Row],[MUJER]] -> 11 | M17: 0 | N17: 0 | O17: 0 | P17: 0 | Q17: 9 | R17: 2 | S17: =EDUVIAL_2023[[#This Row],[PRIMERA INFANCIA (Hasta 5 años)]]+EDUVIAL_2023[[#This Row],[INFANCIA (6 a 11 años)]]+EDUVIAL_2023[[#This Row],[ADOLESCENCIA (12 años a 17 años)]]+EDUVIAL_2023[[#This Row],[ADULTOS-JÓVENES (18 años a 28 años)]]+EDUVIAL_2023[[#This Row],[PERSONAS MAYORES ( Mayores de 60 años)]]+EDUVIAL_2023[[#This Row],[ADULTOS (29 años a 60 años)]] -> 11 | T17: =EDUVIAL_2023[[#This Row],[TOTAL SEXO]] -> 11 | U17: =VLOOKUP(EDUVIAL_2023[[#This Row],[INSTITUCIÓN O EMPRESA]],LISTAS!$J$1:$M$81,3,0) -> Zona 9 | V17: =VLOOKUP(EDUVIAL_2023[[#This Row],[INSTITUCIÓN O EMPRESA]],LISTAS!$J$1:$M$81,4,0) -> Barrio Mesa | W17: =VLOOKUP(EDUVIAL_2023[[#This Row],[INSTITUCIÓN O EMPRESA]],LISTAS!$J$1:$M$81,2,0) -> 6.165319, -75.581362 | X17: =EXACT(EDUVIAL_2023[[#This Row],[TOTAL SEXO]],EDUVIAL_2023[[#This Row],[TOTAL RANGOS]]) -> TRUE
A18: 45706 | B18: FEB | C18: Educación vial en instituciones educativas | D18: Docentes de secundaria instituciones educativas | E18: Formación para el fortalecimiento de conocimientos, hábitos y comportamientos seguros | F18: Jairo Gaviria | G18: Reunion de planeacion de las actividades de educacion vial con docentes,padrs de familia y alumnos | H18: I.E JOSE MANUEL RESTREPO VELEZ | I18: Bairon Sepulveda | J18: 2 | K18: 4 | L18: =EDUVIAL_2023[[#This Row],[HOMBRE]]+EDUVIAL_2023[[#This Row],[MUJER]] -> 6 | M18: 0 | N18: 0 | O18: 0 | P18: 0 | Q18: 6 | R18: 0 | S18: =EDUVIAL_2023[[#This Row],[PRIMERA INFANCIA (Hasta 5 años)]]+EDUVIAL_2023[[#This Row],[INFANCIA (6 a 11 años)]]+EDUVIAL_2023[[#This Row],[ADOLESCENCIA (12 años a 17 años)]]+EDUVIAL_2023[[#This Row],[ADULTOS-JÓVENES (18 años a 28 años)]]+EDUVIAL_2023[[#This Row],[PERSONAS MAYORES ( Mayores de 60 años)]]+EDUVIAL_2023[[#This Row],[ADULTOS (29 años a 60 años)]] -> 6 | T18: =EDUVIAL_2023[[#This Row],[TOTAL SEXO]] -> 6 | U18: =VLOOKUP(EDUVIAL_2023[[#This Row],[INSTITUCIÓN O EMPRESA]],LISTAS!$J$1:$M$81,3,0) -> Zona 8 | V18: Alcalà | W18: =VLOOKUP(EDUVIAL_2023[[#This Row],[INSTITUCIÓN O EMPRESA]],LISTAS!$J$1:$M$81,2,0) -> 6.171594, -75.591214 | X18: =EXACT(EDUVIAL_2023[[#This Row],[TOTAL SEXO]],EDUVIAL_2023[[#This Row],[TOTAL RANGOS]]) -> TRUE
A19: 45706 | B19: FEB | C19: Educación vial en instituciones educativas | D19: Empleados de empresas comerciales y de servicios del municipio | F19: Jairo Gaviria | G19: Reunion de planeacion de seguimiento a los PME de las diferentes instituciones educativas del municipio | H19: Secretaria de Educacion | I19: Veronica Usuga | J19: 0 | K19: 1 | L19: =EDUVIAL_2023[[#This Row],[HOMBRE]]+EDUVIAL_2023[[#This Row],[MUJER]] -> 1 | M19: 0 | N19: 0 | O19: 0 | P19: 0 | Q19: 1 | R19: 0 | S19: =EDUVIAL_2023[[#This Row],[PRIMERA INFANCIA (Hasta 5 años)]]+EDUVIAL_2023[[#This Row],[INFANCIA (6 a 11 años)]]+EDUVIAL_2023[[#This Row],[ADOLESCENCIA (12 años a 17 años)]]+EDUVIAL_2023[[#This Row],[ADULTOS-JÓVENES (18 años a 28 años)]]+EDUVIAL_2023[[#This Row],[PERSONAS MAYORES ( Mayores de 60 años)]]+EDUVIAL_2023[[#This Row],[ADULTOS (29 años a 60 años)]] -> 1 | T19: =EDUVIAL_2023[[#This Row],[TOTAL SEXO]] -> 1 | U19: Zona 8 | V19: Alcalà | W19: 6.171594, -75.591214 | X19: =EXACT(EDUVIAL_2023[[#This Row],[TOTAL SEXO]],EDUVIAL_2023[[#This Row],[TOTAL RANGOS]]) -> TRUE
A20: 45707 | B20: FEB | C20: Educación vial en empresas | D20: Empleados de empresas comerciales y de servicios del municipio | E20: Formación en funciones de auxiliar de tránsito | F20: Jairo Gaviria | G20: Reunion de planeacion de las actividades de formacion para el personal de cuencas | H20: ENVIASEO | I20: Juan Carlos Carmona | J20: 2 | K20: 0 | L20: =EDUVIAL_2023[[#This Row],[HOMBRE]]+EDUVIAL_2023[[#This Row],[MUJER]] -> 2 | M20: 0 | N20: 0 | O20: 0 | P20: 0 | Q20: 2 | R20: 0 | S20: =EDUVIAL_2023[[#This Row],[PRIMERA INFANCIA (Hasta 5 años)]]+EDUVIAL_2023[[#This Row],[INFANCIA (6 a 11 años)]]+EDUVIAL_2023[[#This Row],[ADOLESCENCIA (12 años a 17 años)]]+EDUVIAL_2023[[#This Row],[ADULTOS-JÓVENES (18 años a 28 años)]]+EDUVIAL_2023[[#This Row],[PERSONAS MAYORES ( Mayores de 60 años)]]+EDUVIAL_2023[[#This Row],[ADULTOS (29 años a 60 años)]] -> 2 | T20: =EDUVIAL_2023[[#This Row],[TOTAL SEXO]] -> 2 | U20: Zona 9 | V20: Centro | W20: 6.168450558868997, -75.5896412723252 | X20: =EXACT(EDUVIAL_2023[[#This Row],[TOTAL SEXO]],EDUVIAL_2023[[#This Row],[TOTAL RANGOS]]) -> TRUE
A21: 45707 | B21: FEB | C21: Educación vial en instituciones educativas | D21: Docentes de primaria instituciones educativas | E21: Formación para el fortalecimiento de conocimientos, hábitos y comportamientos seguros | F21: Jairo Gaviria | G21: Reunion de planeacion de las actividades de educacion vial con docentes,padrs de familia y alumnos | H21: I.E ALEJANDRO VELEZ BARRIENTOS | I21: Ligia Chacon | J21: 0 | K21: 1 | L21: =EDUVIAL_2023[[#This Row],[HOMBRE]]+EDUVIAL_2023[[#This Row],[MUJER]] -> 1 | M21: 0 | N21: 0 | O21: 0 | P21: 0 | Q21: 1 | R21: 0 | S21: =EDUVIAL_2023[[#This Row],[PRIMERA INFANCIA (Hasta 5 años)]]+EDUVIAL_2023[[#This Row],[INFANCIA (6 a 11 años)]]+EDUVIAL_2023[[#This Row],[ADOLESCENCIA (12 años a 17 años)]]+EDUVIAL_2023[[#This Row],[ADULTOS-JÓVENES (18 años a 28 años)]]+EDUVIAL_2023[[#This Row],[PERSONAS MAYORES ( Mayores de 60 años)]]+EDUVIAL_2023[[#This Row],[ADULTOS (29 años a 60 años)]] -> 1 | T21: =EDUVIAL_2023[[#This Row],[TOTAL SEXO]] -> 1 | U21: Zona 8 | V21: Alcalà | W21: 6.170070, -75.592298 | X21: =EXACT(EDUVIAL_2023[[#This Row],[TOTAL SEXO]],EDUVIAL_2023[[#This Row],[TOTAL RANGOS]]) -> TRUE
A22: 45709 | B22: FEB | C22: Educación vial en instituciones educativas | D22: Padres de familia | E22: Formación para el fortalecimiento de conocimientos, hábitos y comportamientos seguros | F22: Jairo Gaviria | G22: Capacitacion Humanizando la Movilidad | H22: I.E COMERCIAL DE ENVIGADO - SEDE PIO XII | I22: Samira Fonseca | J22: 8 | K22: 20 | L22: =EDUVIAL_2023[[#This Row],[HOMBRE]]+EDUVIAL_2023[[#This Row],[MUJER]] -> 28 | M22: 0 | N22: 0 | O22: 0 | P22: 4 | Q22: 24 | R22: 0 | S22: =EDUVIAL_2023[[#This Row],[PRIMERA INFANCIA (Hasta 5 años)]]+EDUVIAL_2023[[#This Row],[INFANCIA (6 a 11 años)]]+EDUVIAL_2023[[#This Row],[ADOLESCENCIA (12 años a 17 años)]]+EDUVIAL_2023[[#This Row],[ADULTOS-JÓVENES (18 años a 28 años)]]+EDUVIAL_2023[[#This Row],[PERSONAS MAYORES ( Mayores de 60 años)]]+EDUVIAL_2023[[#This Row],[ADULTOS (29 años a 60 años)]] -> 28 | T22: =EDUVIAL_2023[[#This Row],[TOTAL SEXO]] -> 28 | U22: =VLOOKUP(EDUVIAL_2023[[#This Row],[INSTITUCIÓN O EMPRESA]],LISTAS!$J$1:$M$81,3,0) -> Zona 9 | V22: =VLOOKUP(EDUVIAL_2023[[#This Row],[INSTITUCIÓN O EMPRESA]],LISTAS!$J$1:$M$81,4,0) -> Barrio Mesa | W22: =VLOOKUP(EDUVIAL_2023[[#This Row],[INSTITUCIÓN O EMPRESA]],LISTAS!$J$1:$M$81,2,0) -> 6.165319, -75.581362 | X22: =EXACT(EDUVIAL_2023[[#This Row],[TOTAL SEXO]],EDUVIAL_2023[[#This Row],[TOTAL RANGOS]]) -> TRUE
A23: 45710 | B23: FEB | C23: Educación vial en empresas | D23: Colaboradores de las diferentes dependencias de la Alcaldía | E23: Formación para el fortalecimiento de conocimientos, hábitos y comportamientos seguros | F23: Jairo Gaviria | G23: Capacitacion humanizando la Movilidad, manejo y control de la circulaciuon de vehiculos | H23: INDER | I23: Juan Pablo Agudelo | J23: 8 | K23: 12 | L23: =EDUVIAL_2023[[#This Row],[HOMBRE]]+EDUVIAL_2023[[#This Row],[MUJER]] -> 20 | M23: 0 | N23: 0 | O23: 0 | P23: 8 | Q23: 12 | R23: 0 | S23: =EDUVIAL_2023[[#This Row],[PRIMERA INFANCIA (Hasta 5 años)]]+EDUVIAL_2023[[#This Row],[INFANCIA (6 a 11 años)]]+EDUVIAL_2023[[#This Row],[ADOLESCENCIA (12 años a 17 años)]]+EDUVIAL_2023[[#This Row],[ADULTOS-JÓVENES (18 años a 28 años)]]+EDUVIAL_2023[[#This Row],[PERSONAS MAYORES ( Mayores de 60 años)]]+EDUVIAL_2023[[#This Row],[ADULTOS (29 años a 60 años)]] -> 20 | T23: =EDUVIAL_2023[[#This Row],[TOTAL SEXO]] -> 20 | U23: Zona 9 | V23: Centro | W23: 6.168450558868997, -75.5896412723252 | X23: =EXACT(EDUVIAL_2023[[#This Row],[TOTAL SEXO]],EDUVIAL_2023[[#This Row],[TOTAL RANGOS]]) -> TRUE
A24: 45709 | B24: FEB | C24: Patrulla de Tránsito | D24: Padres de familia | E24: Formación para el fortalecimiento de conocimientos, hábitos y comportamientos seguros | F24: Jairo Gaviria | G24: Taller de crecimiento personal. | H24: Secretaría de Movilidad | I24: Jairo Gaviria | J24: 5 | K24: 25 | L24: =EDUVIAL_2023[[#This Row],[HOMBRE]]+EDUVIAL_2023[[#This Row],[MUJER]] -> 30 | M24: 0 | N24: 0 | O24: 0 | P24: 0 | Q24: 30 | R24: 0 | S24: =EDUVIAL_2023[[#This Row],[PRIMERA INFANCIA (Hasta 5 años)]]+EDUVIAL_2023[[#This Row],[INFANCIA (6 a 11 años)]]+EDUVIAL_2023[[#This Row],[ADOLESCENCIA (12 años a 17 años)]]+EDUVIAL_2023[[#This Row],[ADULTOS-JÓVENES (18 años a 28 años)]]+EDUVIAL_2023[[#This Row],[PERSONAS MAYORES ( Mayores de 60 años)]]+EDUVIAL_2023[[#This Row],[ADULTOS (29 años a 60 años)]] -> 30 | T24: =T20 -> 2 | U24: Zona 9 | V24: Los Naranjos | W24: 6.169505127932036, -75.58258243619996 | X24: =EXACT(EDUVIAL_2023[[#This Row],[TOTAL SEXO]],EDUVIAL_2023[[#This Row],[TOTAL RANGOS]]) -> TRUE
A25: 45712 | B25: FEB | C25: Experiencias ciudadanas en movilidad sostenible y segura | D25: Conductores sancionados por embriaguez | E25: Orientación y seguimiento a labor comunitaria | F25: Daniel Ríos | G25: Sensibilización en prevención de la conducción bajo los efectos del alcohol o sustancias psicoactivas. | H25: Secretaría de Movilidad | I25: Alejandro Guzman Duque | J25: 1 | L25: =EDUVIAL_2023[[#This Row],[HOMBRE]]+EDUVIAL_2023[[#This Row],[MUJER]] -> 1 | M25: 0 | N25: 0 | O25: 0 | P25: 0 | Q25: 1 | R25: 0 | S25: =EDUVIAL_2023[[#This Row],[PRIMERA INFANCIA (Hasta 5 años)]]+EDUVIAL_2023[[#This Row],[INFANCIA (6 a 11 años)]]+EDUVIAL_2023[[#This Row],[ADOLESCENCIA (12 años a 17 años)]]+EDUVIAL_2023[[#This Row],[ADULTOS-JÓVENES (18 años a 28 años)]]+EDUVIAL_2023[[#This Row],[PERSONAS MAYORES ( Mayores de 60 años)]]+EDUVIAL_2023[[#This Row],[ADULTOS (29 años a 60 años)]] -> 1 | T25: =EDUVIAL_2023[[#This Row],[TOTAL SEXO]] -> 1 | U25: Zona 9 | V25: Centro | W25: 6.168450558868997, -75.5896412723252 | X25: =EXACT(EDUVIAL_2023[[#This Row],[TOTAL SEXO]],EDUVIAL_2023[[#This Row],[TOTAL RANGOS]]) -> TRUE
A26: 45713 | B26: FEB | C26: Educación vial en empresas | D26: Colaboradores de diferentes dependeancias de la alcaldia | E26: Formación para el fortalecimiento de conocimientos, hábitos y comportamientos seguros | F26: Jairo Gaviria | G26: Capacitacion humanizando la Movilidad al personal de ambien-servicios manejo y control de la circulaciuon de vehiculos | H26: ENVIASEO | I26: Juan Carlos Carmona | J26: 46 | K26: 4 | L26: =EDUVIAL_2023[[#This Row],[HOMBRE]]+EDUVIAL_2023[[#This Row],[MUJER]] -> 50 | M26: 0 | N26: 0 | O26: 0 | P26: 0 | Q26: 50 | R26: 0 | S26: =EDUVIAL_2023[[#This Row],[PRIMERA INFANCIA (Hasta 5 años)]]+EDUVIAL_2023[[#This Row],[INFANCIA (6 a 11 años)]]+EDUVIAL_2023[[#This Row],[ADOLESCENCIA (12 años a 17 años)]]+EDUVIAL_2023[[#This Row],[ADULTOS-JÓVENES (18 años a 28 años)]]+EDUVIAL_2023[[#This Row],[PERSONAS MAYORES ( Mayores de 60 años)]]+EDUVIAL_2023[[#This Row],[ADULTOS (29 años a 60 años)]] -> 50 | T26: =EDUVIAL_2023[[#This Row],[TOTAL SEXO]] -> 50 | U26: Zona 8 | V26: Alcalà | W26: 6.170816056852942, -75.59078118374059 | X26: =EXACT(EDUVIAL_2023[[#This Row],[TOTAL SEXO]],EDUVIAL_2023[[#This Row],[TOTAL RANGOS]]) -> TRUE
A27: 45713 | B27: FEB | C27: Educación vial en empresas | D27: Colaboradores de diferentes dependeancias de la alcaldia | E27: Formación para el fortalecimiento de conocimientos, hábitos y comportamientos seguros | F27: Daniel Ríos | G27: Capacitacion humanizando la Movilidad, manejo y control de la circulaciuon de vehiculos, Recomendaciones movilidad segura. | H27: Secretaría de Movilidad | I27: Giovany Perez | J27: 9 | K27: 1 | L27: =EDUVIAL_2023[[#This Row],[HOMBRE]]+EDUVIAL_2023[[#This Row],[MUJER]] -> 10 | M27: 0 | N27: 0 | O27: 0 | P27: 0 | Q27: 10 | R27: 0 | S27: =EDUVIAL_2023[[#This Row],[PRIMERA INFANCIA (Hasta 5 años)]]+EDUVIAL_2023[[#This Row],[INFANCIA (6 a 11 años)]]+EDUVIAL_2023[[#This Row],[ADOLESCENCIA (12 años a 17 años)]]+EDUVIAL_2023[[#This Row],[ADULTOS-JÓVENES (18 años a 28 años)]]+EDUVIAL_2023[[#This Row],[PERSONAS MAYORES ( Mayores de 60 años)]]+EDUVIAL_2023[[#This Row],[ADULTOS (29 años a 60 años)]] -> 10 | T27: =EDUVIAL_2023[[#This Row],[TOTAL SEXO]] -> 10 | U27: Zona 9 | V27: Centro | W27: 6.168450558868997, -75.5896412723252 | X27: =EXACT(EDUVIAL_2023[[#This Row],[TOTAL SEXO]],EDUVIAL_2023[[#This Row],[TOTAL RANGOS]]) -> TRUE
A28: 45713 | B28: FEB | C28: Educación vial en instituciones educativas | D28: Docentes de primaria instituciones educativas | E28: Formación para el fortalecimiento de conocimientos, hábitos y comportamientos seguros | F28: Daniel Ríos | G28: Taller transversalidad de las areas del conocimiento con movilidad | H28: I.E JOSE MANUEL RESTREPO VELEZ | I28: Bairon Sepulveda | J28: 9 | K28: 13 | L28: =EDUVIAL_2023[[#This Row],[HOMBRE]]+EDUVIAL_2023[[#This Row],[MUJER]] -> 22 | M28: 0 | N28: 0 | O28: 0 | P28: 0 | Q28: 22 | R28: 0 | S28: =EDUVIAL_2023[[#This Row],[PRIMERA INFANCIA (Hasta 5 años)]]+EDUVIAL_2023[[#This Row],[INFANCIA (6 a 11 años)]]+EDUVIAL_2023[[#This Row],[ADOLESCENCIA (12 años a 17 años)]]+EDUVIAL_2023[[#This Row],[ADULTOS-JÓVENES (18 años a 28 años)]]+EDUVIAL_2023[[#This Row],[PERSONAS MAYORES ( Mayores de 60 años)]]+EDUVIAL_2023[[#This Row],[ADULTOS (29 años a 60 años)]] -> 22 | T28: =EDUVIAL_2023[[#This Row],[TOTAL SEXO]] -> 22 | U28: =VLOOKUP(EDUVIAL_2023[[#This Row],[INSTITUCIÓN O EMPRESA]],LISTAS!$J$1:$M$81,3,0) -> Zona 8 | V28: Alcalà | W28: =VLOOKUP(EDUVIAL_2023[[#This Row],[INSTITUCIÓN O EMPRESA]],LISTAS!$J$1:$M$81,2,0) -> 6.171594, -75.591214 | X28: =EXACT(EDUVIAL_2023[[#This Row],[TOTAL SEXO]],EDUVIAL_2023[[#This Row],[TOTAL RANGOS]]) -> TRUE
A29: 45715 | B29: FEB | C29: Educación vial en empresas | D29: Colaboradores de las diferentes dependencias de la Alcaldía | E29: Formación para el fortalecimiento de conocimientos, hábitos y comportamientos seguros | F29: Daniel Ríos | G29: Capacitacion humanizando la Movilidad, manejo y control de la circulaciuon de vehiculos, Recomendaciones movilidad segura. | H29: ENVIASEO | I29: Juan carlos Carmona | J29: 3 | K29: 4 | L29: =EDUVIAL_2023[[#This Row],[HOMBRE]]+EDUVIAL_2023[[#This Row],[MUJER]] -> 7 | M29: 0 | N29: 0 | O29: 0 | P29: 0 | Q29: 7 | R29: 0 | S29: =EDUVIAL_2023[[#This Row],[PRIMERA INFANCIA (Hasta 5 años)]]+EDUVIAL_2023[[#This Row],[INFANCIA (6 a 11 años)]]+EDUVIAL_2023[[#This Row],[ADOLESCENCIA (12 años a 17 años)]]+EDUVIAL_2023[[#This Row],[ADULTOS-JÓVENES (18 años a 28 años)]]+EDUVIAL_2023[[#This Row],[PERSONAS MAYORES ( Mayores de 60 años)]]+EDUVIAL_2023[[#This Row],[ADULTOS (29 años a 60 años)]] -> 7 | T29: =EDUVIAL_2023[[#This Row],[TOTAL SEXO]] -> 7 | U29: Zona 9 | V29: Centro | W29: 6.167664, -75.586311 | X29: =EXACT(EDUVIAL_2023[[#This Row],[TOTAL SEXO]],EDUVIAL_2023[[#This Row],[TOTAL RANGOS]]) -> TRUE
A30: 45716 | B30: FEB | C30: Educación vial en instituciones educativas | D30: Docentes de secundaria instituciones educativas | E30: Reunión de planeación para actividades | F30: Jairo Gaviria | G30: Reunion de planeacion de las actividades de educacion vial con docentes,padrs de familia y alumnos | H30: I.E LAS PALMAS | I30: Jorge marulanda | J30: 1 | K30: 1 | L30: =EDUVIAL_2023[[#This Row],[HOMBRE]]+EDUVIAL_2023[[#This Row],[MUJER]] -> 2 | M30: 0 | N30: 0 | O30: 0 | P30: 0 | Q30: 2 | R30: 0 | S30: =EDUVIAL_2023[[#This Row],[PRIMERA INFANCIA (Hasta 5 años)]]+EDUVIAL_2023[[#This Row],[INFANCIA (6 a 11 años)]]+EDUVIAL_2023[[#This Row],[ADOLESCENCIA (12 años a 17 años)]]+EDUVIAL_2023[[#This Row],[ADULTOS-JÓVENES (18 años a 28 años)]]+EDUVIAL_2023[[#This Row],[PERSONAS MAYORES ( Mayores de 60 años)]]+EDUVIAL_2023[[#This Row],[ADULTOS (29 años a 60 años)]] -> 2 | T30: =EDUVIAL_2023[[#This Row],[TOTAL SEXO]] -> 2 | U30: =VLOOKUP(EDUVIAL_2023[[#This Row],[INSTITUCIÓN O EMPRESA]],LISTAS!$J$1:$M$81,3,0) -> Zona 12 | V30: =VLOOKUP(EDUVIAL_2023[[#This Row],[INSTITUCIÓN O EMPRESA]],LISTAS!$J$1:$M$81,4,0) -> Vereda Las Palmas | W30: =VLOOKUP(EDUVIAL_2023[[#This Row],[INSTITUCIÓN O EMPRESA]],LISTAS!$J$1:$M$81,2,0) -> 6.151222, -75.533765 | X30: =EXACT(EDUVIAL_2023[[#This Row],[TOTAL SEXO]],EDUVIAL_2023[[#This Row],[TOTAL RANGOS]]) -> TRUE
A31: 45720 | B31: MAR | C31: Acciones Por La Vida - ANSV | D31: Motociclistas | E31: Acciones por la vida para motociclistas ANSV | F31: Daniel Ríos | G31: Desarrollar actividades pedagógicas y artísticas en vía para mitigar conductas de riesgo que están asociadas a los siniestros viales | H31: Agencia Nacional de Seguridad Vial | I31: Joyce Velez | J31: 87 | K31: 15 | L31: =EDUVIAL_2023[[#This Row],[HOMBRE]]+EDUVIAL_2023[[#This Row],[MUJER]] -> 102 | M31: 0 | N31: 0 | O31: 0 | P31: 26 | Q31: 66 | R31: 10 | S31: =EDUVIAL_2023[[#This Row],[PRIMERA INFANCIA (Hasta 5 años)]]+EDUVIAL_2023[[#This Row],[INFANCIA (6 a 11 años)]]+EDUVIAL_2023[[#This Row],[ADOLESCENCIA (12 años a 17 años)]]+EDUVIAL_2023[[#This Row],[ADULTOS-JÓVENES (18 años a 28 años)]]+EDUVIAL_2023[[#This Row],[PERSONAS MAYORES ( Mayores de 60 años)]]+EDUVIAL_2023[[#This Row],[ADULTOS (29 años a 60 años)]] -> 102 | T31: =EDUVIAL_2023[[#This Row],[TOTAL SEXO]] -> 102 | U31: Zona 9 | V31: Centro | W31: 6.167664, -75.586311 | X31: =EXACT(EDUVIAL_2023[[#This Row],[TOTAL SEXO]],EDUVIAL_2023[[#This Row],[TOTAL RANGOS]]) -> TRUE
A32: 45721 | B32: MAR | C32: Experiencias ciudadanas en movilidad sostenible y segura | D32: Conductores sancionados por embriaguez | E32: Orientación y seguimiento a labor comunitaria | F32: Jairo Gaviria | G32: Sensibilización en prevención de la conducción bajo los efectos del alcohol o sustancias psicoactivas. | H32: Secretaría de Movilidad | I32: Maria Piedad Arango V. | J32: 0 | K32: 1 | L32: =EDUVIAL_2023[[#This Row],[HOMBRE]]+EDUVIAL_2023[[#This Row],[MUJER]] -> 1 | M32: 0 | N32: 0 | O32: 0 | P32: 0 | Q32: 1 | R32: 0 | S32: =EDUVIAL_2023[[#This Row],[PRIMERA INFANCIA (Hasta 5 años)]]+EDUVIAL_2023[[#This Row],[INFANCIA (6 a 11 años)]]+EDUVIAL_2023[[#This Row],[ADOLESCENCIA (12 años a 17 años)]]+EDUVIAL_2023[[#This Row],[ADULTOS-JÓVENES (18 años a 28 años)]]+EDUVIAL_2023[[#This Row],[PERSONAS MAYORES ( Mayores de 60 años)]]+EDUVIAL_2023[[#This Row],[ADULTOS (29 años a 60 años)]] -> 1 | T32: =EDUVIAL_2023[[#This Row],[TOTAL SEXO]] -> 1 | U32: Zona 9 | V32: Centro | W32: 6.167664, -75.586311 | X32: =EXACT(EDUVIAL_2023[[#This Row],[TOTAL SEXO]],EDUVIAL_2023[[#This Row],[TOTAL RANGOS]]) -> TRUE
A33: 45722 | B33: MAR | C33: Acciones por la vida - ANSV | D33: Motociclistas | E33: Acciones por la vida para motociclistas ANSV | F33: Daniel Ríos | G33: Desarrollar actividades pedagógicas y artísticas en vía para mitigar conductas de riesgo que están asociadas a los siniestros viales | H33: Agencia Nacional de Seguridad Vial | I33: Joyce Velez | J33: 50 | K33: 9 | L33: =EDUVIAL_2023[[#This Row],[HOMBRE]]+EDUVIAL_2023[[#This Row],[MUJER]] -> 59 | M33: 0 | N33: 0 | O33: 0 | P33: 14 | Q33: 42 | R33: 3 | S33: =EDUVIAL_2023[[#This Row],[PRIMERA INFANCIA (Hasta 5 años)]]+EDUVIAL_2023[[#This Row],[INFANCIA (6 a 11 años)]]+EDUVIAL_2023[[#This Row],[ADOLESCENCIA (12 años a 17 años)]]+EDUVIAL_2023[[#This Row],[ADULTOS-JÓVENES (18 años a 28 años)]]+EDUVIAL_2023[[#This Row],[PERSONAS MAYORES ( Mayores de 60 años)]]+EDUVIAL_2023[[#This Row],[ADULTOS (29 años a 60 años)]] -> 59 | T33: =EDUVIAL_2023[[#This Row],[TOTAL SEXO]] -> 59 | U33: Zona 9 | V33: Centro | W33: 6.167664, -75.586311 | X33: =EXACT(EDUVIAL_2023[[#This Row],[TOTAL SEXO]],EDUVIAL_2023[[#This Row],[TOTAL RANGOS]]) -> TRUE
A34: 45725 | B34: MAR | C34: Experiencias ciudadanas en movilidad sostenible y segura | D34: Ciclistas | E34: Enviciescuela. Actividad experiencial en bicicleta | F34: Jairo Gaviria | G34: Apoyo en la celebracion del dia internacional de la ciclovia con el programa de ENVICIESCUELA | H34: Inder | I34: Juan pablo Agude Zorrilla | J34: 10 | K34: 9 | L34: =EDUVIAL_2023[[#This Row],[HOMBRE]]+EDUVIAL_2023[[#This Row],[MUJER]] -> 19 | M34: 2 | N34: 0 | O34: 8 | P34: 0 | Q34: 9 | R34: 0 | S34: =EDUVIAL_2023[[#This Row],[PRIMERA INFANCIA (Hasta 5 años)]]+EDUVIAL_2023[[#This Row],[INFANCIA (6 a 11 años)]]+EDUVIAL_2023[[#This Row],[ADOLESCENCIA (12 años a 17 años)]]+EDUVIAL_2023[[#This Row],[ADULTOS-JÓVENES (18 años a 28 años)]]+EDUVIAL_2023[[#This Row],[PERSONAS MAYORES ( Mayores de 60 años)]]+EDUVIAL_2023[[#This Row],[ADULTOS (29 años a 60 años)]] -> 19 | T34: =EDUVIAL_2023[[#This Row],[TOTAL SEXO]] -> 19 | U34: Zona 1 | V34: Las Vegas | W34: 6.165622783551734, -75.5992929118132 | X34: =EXACT(EDUVIAL_2023[[#This Row],[TOTAL SEXO]],EDUVIAL_2023[[#This Row],[TOTAL RANGOS]]) -> TRUE
A35: 45726 | B35: MAR | C35: Educación vial en instituciones educativas | D35: Padres de familia | E35: Sensibilización en movilidad sostenible y segura | F35: Jairo Gaviria | G35: Capacitacion en educacion y seguridad vial con la capacitacion humanizando la movilidad a un grupo de padres | H35: CENTRO EDUCATIVO LA GACELA | I35: Angela Gomez | J35: 4 | K35: 5 | L35: =EDUVIAL_2023[[#This Row],[HOMBRE]]+EDUVIAL_2023[[#This Row],[MUJER]] -> 9 | M35: 0 | N35: 0 | O35: 0 | P35: 1 | Q35: 7 | R35: 1 | S35: =EDUVIAL_2023[[#This Row],[PRIMERA INFANCIA (Hasta 5 años)]]+EDUVIAL_2023[[#This Row],[INFANCIA (6 a 11 años)]]+EDUVIAL_2023[[#This Row],[ADOLESCENCIA (12 años a 17 años)]]+EDUVIAL_2023[[#This Row],[ADULTOS-JÓVENES (18 años a 28 años)]]+EDUVIAL_2023[[#This Row],[PERSONAS MAYORES ( Mayores de 60 años)]]+EDUVIAL_2023[[#This Row],[ADULTOS (29 años a 60 años)]] -> 9 | T35: =EDUVIAL_2023[[#This Row],[TOTAL SEXO]] -> 9 | U35: Zona 7 | V35: Alto de las Flores | W35: 6.15584144850407, -75.60075331324106 | X35: =EXACT(EDUVIAL_2023[[#This Row],[TOTAL SEXO]],EDUVIAL_2023[[#This Row],[TOTAL RANGOS]]) -> TRUE
A36: 45727 | B36: MAR | C36: Educación vial en instituciones educativas | D36: Padres de familia | E36: Sensibilización en movilidad sostenible y segura | F36: Jairo Gaviria | G36: Capacitacion en educacion y seguridad vial con la capacitacion humanizando la movilidad a un grupo de padres | H36: CDI MICHIN | I36: Gloria Patricia Mejia | J36: 0 | K36: 9 | L36: =EDUVIAL_2023[[#This Row],[HOMBRE]]+EDUVIAL_2023[[#This Row],[MUJER]] -> 9 | M36: 0 | N36: 0 | O36: 0 | P36: 3 | Q36: 4 | R36: 2 | S36: =EDUVIAL_2023[[#This Row],[PRIMERA INFANCIA (Hasta 5 años)]]+EDUVIAL_2023[[#This Row],[INFANCIA (6 a 11 años)]]+EDUVIAL_2023[[#This Row],[ADOLESCENCIA (12 años a 17 años)]]+EDUVIAL_2023[[#This Row],[ADULTOS-JÓVENES (18 años a 28 años)]]+EDUVIAL_2023[[#This Row],[PERSONAS MAYORES ( Mayores de 60 años)]]+EDUVIAL_2023[[#This Row],[ADULTOS (29 años a 60 años)]] -> 9 | T36: =EDUVIAL_2023[[#This Row],[TOTAL SEXO]] -> 9 | U36: Zona 8 | V36: Alcalà | W36: 6.170816056852942, -75.59078118374059 | X36: =EXACT(EDUVIAL_2023[[#This Row],[TOTAL SEXO]],EDUVIAL_2023[[#This Row],[TOTAL RANGOS]]) -> TRUE
A37: 45728 | B37: MAR | C37: Educación vial en instituciones educativas | D37: Administrativos instituciones educativas | E37: Reunión de planeación para actividades | F37: Jairo Gaviria | G37: Reunion de planeacion de las estrategias de educacion vial para docentes,padres de familia y alumnos | H37: I.E MARTIN EDUARDO RIOS | I37: Veronica Usuga | J37: 1 | K37: 1 | L37: =EDUVIAL_2023[[#This Row],[HOMBRE]]+EDUVIAL_2023[[#This Row],[MUJER]] -> 2 | M37: 0 | N37: 0 | O37: 0 | P37: 0 | Q37: 2 | R37: 0 | S37: =EDUVIAL_2023[[#This Row],[PRIMERA INFANCIA (Hasta 5 años)]]+EDUVIAL_2023[[#This Row],[INFANCIA (6 a 11 años)]]+EDUVIAL_2023[[#This Row],[ADOLESCENCIA (12 años a 17 años)]]+EDUVIAL_2023[[#This Row],[ADULTOS-JÓVENES (18 años a 28 años)]]+EDUVIAL_2023[[#This Row],[PERSONAS MAYORES ( Mayores de 60 años)]]+EDUVIAL_2023[[#This Row],[ADULTOS (29 años a 60 años)]] -> 2 | T37: =EDUVIAL_2023[[#This Row],[TOTAL SEXO]] -> 2 | U37: Zona 13 | V37: Vereda Pantanillo | W37: 6.186791, -75.490075 | X37: =EXACT(EDUVIAL_2023[[#This Row],[TOTAL SEXO]],EDUVIAL_2023[[#This Row],[TOTAL RANGOS]]) -> TRUE
A38: 45728 | B38: MAR | C38: Acciones por la vida - ANSV | D38: Motociclistas | E38: Acciones por la vida para motociclistas ANSV | F38: Jairo Gaviria | G38: Desarrollar actividades pedagógicas y artísticas en vía para mitigar conductas de riesgo que están asociadas a los siniestros viales | H38: Agencia Nacional de Seguridad Vial | I38: Joyce Velez | J38: 35 | K38: 4 | L38: =EDUVIAL_2023[[#This Row],[HOMBRE]]+EDUVIAL_2023[[#This Row],[MUJER]] -> 39 | P38: 2 | Q38: 36 | R38: 1 | S38: =EDUVIAL_2023[[#This Row],[PRIMERA INFANCIA (Hasta 5 años)]]+EDUVIAL_2023[[#This Row],[INFANCIA (6 a 11 años)]]+EDUVIAL_2023[[#This Row],[ADOLESCENCIA (12 años a 17 años)]]+EDUVIAL_2023[[#This Row],[ADULTOS-JÓVENES (18 años a 28 años)]]+EDUVIAL_2023[[#This Row],[PERSONAS MAYORES ( Mayores de 60 años)]]+EDUVIAL_2023[[#This Row],[ADULTOS (29 años a 60 años)]] -> 39 | T38: =EDUVIAL_2023[[#This Row],[TOTAL SEXO]] -> 39 | U38: Zona 9 | V38: Centro | W38: 6.167664, -75.586311 | X38: =EXACT(EDUVIAL_2023[[#This Row],[TOTAL SEXO]],EDUVIAL_2023[[#This Row],[TOTAL RANGOS]]) -> TRUE
A39: 45728 | B39: MAR | C39: Educación vial en instituciones educativas | D39: Administrativos instituciones educativas | E39: Reunión de planeación para actividades | F39: Jairo Gaviria | G39: Reunion de planeacion de las estrategias de educacion vial para docentes,padres de familia y alumnos | H39: I.E LA PAZ | I39: Ruben Alcala | J39: 2 | L39: =EDUVIAL_2023[[#This Row],[HOMBRE]]+EDUVIAL_2023[[#This Row],[MUJER]] -> 2 | Q39: 2 | S39: =EDUVIAL_2023[[#This Row],[PRIMERA INFANCIA (Hasta 5 años)]]+EDUVIAL_2023[[#This Row],[INFANCIA (6 a 11 años)]]+EDUVIAL_2023[[#This Row],[ADOLESCENCIA (12 años a 17 años)]]+EDUVIAL_2023[[#This Row],[ADULTOS-JÓVENES (18 años a 28 años)]]+EDUVIAL_2023[[#This Row],[PERSONAS MAYORES ( Mayores de 60 años)]]+EDUVIAL_2023[[#This Row],[ADULTOS (29 años a 60 años)]] -> 2 | T39: =EDUVIAL_2023[[#This Row],[TOTAL SEXO]] -> 2 | U39: =VLOOKUP(EDUVIAL_2023[[#This Row],[INSTITUCIÓN O EMPRESA]],LISTAS!$J$1:$M$81,3,0) -> Zona 7 | V39: =VLOOKUP(EDUVIAL_2023[[#This Row],[INSTITUCIÓN O EMPRESA]],LISTAS!$J$1:$M$81,4,0) -> La Paz | W39: =VLOOKUP(EDUVIAL_2023[[#This Row],[INSTITUCIÓN O EMPRESA]],LISTAS!$J$1:$M$81,2,0) -> 6.162272, -75.594035 | X39: =EXACT(EDUVIAL_2023[[#This Row],[TOTAL SEXO]],EDUVIAL_2023[[#This Row],[TOTAL RANGOS]]) -> TRUE
A40: 45729 | B40: MAR | C40: Educación vial en instituciones educativas | D40: Administrativos instituciones educativas | E40: Reunión de planeación para actividades | F40: Jairo Gaviria | G40: Reunion de planeacion de las estrategias de educacion vial para docentes,padres de familia y alumnos | H40: I.E MARIA POUSSSEPIN | I40: Veronica Usuga | J40: 3 | K40: 1 | L40: =EDUVIAL_2023[[#This Row],[HOMBRE]]+EDUVIAL_2023[[#This Row],[MUJER]] -> 4 | M40: 0 | N40: 0 | O40: 0 | P40: 0 | Q40: 4 | S40: =EDUVIAL_2023[[#This Row],[PRIMERA INFANCIA (Hasta 5 años)]]+EDUVIAL_2023[[#This Row],[INFANCIA (6 a 11 años)]]+EDUVIAL_2023[[#This Row],[ADOLESCENCIA (12 años a 17 años)]]+EDUVIAL_2023[[#This Row],[ADULTOS-JÓVENES (18 años a 28 años)]]+EDUVIAL_2023[[#This Row],[PERSONAS MAYORES ( Mayores de 60 años)]]+EDUVIAL_2023[[#This Row],[ADULTOS (29 años a 60 años)]] -> 4 | T40: =EDUVIAL_2023[[#This Row],[TOTAL SEXO]] -> 4 | U40: Zona 3 | V40: Uribe Ángel | W40: 6.171157, -75.577011 | X40: =EXACT(EDUVIAL_2023[[#This Row],[TOTAL SEXO]],EDUVIAL_2023[[#This Row],[TOTAL RANGOS]]) -> TRUE
...

Sheet FORMACION CIUDADANA I TR
E2: INDICADORES DE GESTIÓN FORMACION CIUDADANA 2024
B9: TRIMESTRE | C9: PRIMER
B11: INDICADOR | C11: Variación de la Demanda
B12: DESCRIPCION | C12: Expresa la variación en la demanda de los servicios de una secretaría por parte de la comunidad respecto de un periodo a otro
B13: FORMULA | C13: (Numero solicitudes Solucionadas Periodo Actual - Numero Solicitudes Solucionadas Periodo Anterior) / Numero Solicitudes Solucionadas Periodo anterior * 100
B15: Suma de TOTAL SEXO | C15: PÚBLICOS
B16: MES | C16: Agentes de Tránsito | D16: Auxiliares de tránsito | E16: Ciclistas | F16: Colaboradores de las diferentes dependencias de la Alcaldía | G16: Conductores de transporte público (taxis) | H16: Conductores en general | I16: Conductores sancionados por embriaguez | J16: Docentes de primaria instituciones educativas | K16: Docentes de secundaria instituciones educativas | L16: Empleados de empresas comerciales y de servicios del municipio | M16: Estudiantes primaria | N16: Estudiantes secundaria | O16: Integrantes patrulla de trànsito | P16: Motociclistas | Q16: Niños y niñas de 4 a 7 años | R16: Padres de familia | S16: Peatones | T16: Personas mayores | U16: Población en general | V16: Rectores de instituciones educativas | W16: Transportadores escolares | X16: Total general trimestre
B17: ENE | I17: 1 | K17: 1 | W17: 16 | X17: 18
B18: FEB | D18: 7 | F18: 124 | H18: 54 | I18: 1 | J18: 1 | K18: 5 | X18: 192
B19: MAR | D19: 7 | E19: 20 | F19: 26 | H19: 36 | I19: 5 | L19: 7 | P19: 42 | R19: 15 | S19: 250 | X19: 408
B20: ABR | D20: 5 | E20: 41 | F20: 2 | G20: 5 | I20: 2 | J20: 44 | K20: 2 | M20: 275 | N20: 254 | Q20: 619 | T20: 22 | U20: 358 | V20: 60 | X20: 1689
B21: MAY | C21: 17 | D21: 8 | F21: 44 | I21: 2 | J21: 20 | K21: 9 | L21: 75 | M21: 598 | N21: 5 | O21: 37 | P21: 208 | R21: 83 | U21: 14 | X21: 1120
B22: Total general trimestre | C22: 17 | D22: 27 | E22: 61 | F22: 196 | G22: 5 | H22: 90 | I22: 11 | J22: 65 | K22: 17 | L22: 82 | M22: 873 | N22: 259 | O22: 37 | P22: 250 | Q22: 619 | R22: 98 | S22: 250 | T22: 22 | U22: 372 | V22: 60 | W22: 16 | X22: 3427
B31: INDICADOR | C31: OPORTUNIDAD DE SERVICIO
B32: DESCRIPCION | C32: Expresa la relación entre el número de solicitudes de la comunidad frente a los servicios de la secretaria que se resolvieron en el tiempo establecido en el procedimiento sobre el total de solicitudes que fueron atendidas a los usuarios | P32: En el PRIMER TRIMESTRE del año 2024 participaron 618 personas en las diferentes acciones de formación y cultura ciudadana para la movilidad. En comparación al cuarto trimestre del año 2023 se tiene una reducción del 85% de paticipación debido a diferentes situaciones entre ellas: - Estructuración de los indicadores de educación vial en el Plan de Desarrollo 2024-2027. - Inicio del contrato de prestación de servicios para el apoyo de las actividades de educación vial a partir del 19 de febnrero de 2024. - Inicio de las actividades de las instituciones educativas a partir del mes de febrero.
B33: FORMULA | C33: Numero solicitudes de los servicios resueltos a tiempo / numero de solicitudes atendidas) * 100 | M33: TRIM IV - 2022 | N33: 4072
M34: TRIM I - 2023 | N34: 618
B35: El 100% de las solicitudes en el periodo, fueron resueltas en la debida oportunidad . | M35: TRIM II - 2023
M36: TRIM III - 2023
M37: TRIM IV - 2023
B39: INDICADOR | C39: CALIDAD EN EL SERVICIO | M39: TOTAL AÑO 2023 | N39: =N34+N35+N36+N37 -> 618
B40: DESCRIPCION | C40: Se define como la sumatoria del puntaje obtenido en la encuesta de satisfacción realizada a los usuarios atendidos mediante los servicios sobre el numero total de encuestas que fueron aplicadas | M40: % DIFERENCIA ENTRE TRIM III - TRIM IV | N40: =N34-N33 -> -3454
B41: FORMULA | C41: Sumatoria del Puntaje Encuestas de satisfaccion / Numero Total Encuestas Aplicadas
B43: Los asistentes y usuarios de los cursos de seguridad vial en el CUARTO TRIMESTRE del año evaluaron aspectos de Coherencia entre los objetivos del programa y el contenido de la capacitación; asertividad del mensaje según expectativas; Conveniencia de los horarios de clase, el compromiso con el cuidado propio y de los demás, el entendimiento de las normas de tránsito y la responsabilidad individual frente a la práctica de las mismas; otorgando una califcacion de con 4.9 sobre 5.0 por parte de los encuestados. | E43: 62 encuestas | F43: puntaje obtenido 305,2 | G43: calificacion: 4,9
B45: INDICADOR | C45: Cumplimiento al plan
B46: DESCRIPCION | C46: Expresa la relación entre las actividades ejecutadas del plan de formación ciudadana sobre el número total de actividades planeadas
B47: FORMULA | C47: (Actividades Ejecutadas del Plan de Desarrollo en Formación Ciudadana / Actividades Planeadas del Plan de Desarrollo de Formación Ciudadana)*100
B50: DATOS I TRIMESTRE DE 2024
B51: ACTIVIDADES FORMACION CIUDADANA PLAN DE DESARROLLO | C51: Unidad de medida | D51: Forma de acumulación | E51: Meta programada 2024 | F51: EJECUTADO ACUMULADO 2023
B52: Centros integrales de atención implementados y operando | C52: Número | D52: Mantenimiento | E52: 1 | F52: 1
B53: Zonas impactadas con cultura ciudadana para la movilidad | C53: Número | D53: Suma | E53: 3 | F53: 5
B54: Docentes de educación primaria capacitados en el fortalecimiento de las competencias en seguridad vial | C54: Número | D54: Suma | E54: 20 | F54: 1
B55: Docentes de educación secundaria capacitados en el fortalecimiento de las competencias en seguridad vial | C55: Número | D55: Suma | E55: 20 | F55: 6
B56: Instituciones educativas oficiales con proyecto de formación en seguridad vial implementado | C56: Número | D56: Suma | E56: 1 | F56: 3
B57: Estudiantes de las instituciones educativas oficiales beneficiados con los cursos de formación en seguridad vial | C57: Número | D57: Suma | E57: 50 | F57: 0
B59: EL CUMPLIMIENTO DEL PLAN SE DIO ACORDE A LO PROGRAMADO, SUPERANDO EL 100%

Sheet DATOS
E2: INDICADORES DE GESTIÓN FORMACION CIUDADANA 2024
B9: CORTE: 31 DE MAYO DE 2023
B11: MES | C11: (Todas) | F11: MES | G11: (Todas)
B13: ZONAS | C13: Suma de TOTAL SEXO | F13: ACCIONES | G13: Suma de TOTAL SEXO
B14: Zona 1 | C14: 75 | F14: Centro de Educación Vial | G14: 896
B15: Zona 2 | C15: 277 | F15: Educación vial en empresas | G15: 402
B16: Zona 3 | C16: 19 | F16: Educación vial en instituciones educativas | G16: 1097
B17: Zona 4 | C17: 9 | F17: Evento Secretaría de Movilidad | G17: 246
B18: Zona 5 | C18: 274 | F18: Experiencias ciudadanas en movilidad sostenible y segura | G18: 449
B19: Zona 7 | C19: 128 | F19: Patrulla de Tránsito | G19: 299
B20: Zona 8 | C20: 258 | F20: Representación en Comités del municipio | G20: 38
B21: Zona 9 | C21: 1964 | F21: Total general | G21: 3427
B22: Zona 10 | C22: 2
B23: Zona 12 | C23: 100
B24: Zona 6 | C24: 321
B25: Total general | C25: 3427
B30: MES | C30: (Todas)
C32: ZONAS
C33: Zona 1 | D33: Zona 10 | E33: Zona 12 | F33: Zona 2 | G33: Zona 3 | H33: Zona 4 | I33: Zona 5 | J33: Zona 6 | K33: Zona 7 | L33: Zona 8 | M33: Zona 9 | N33: Total general
B34: Suma de TOTAL SEXO | C34: 75 | D34: 2 | E34: 100 | F34: 277 | G34: 19 | H34: 9 | I34: 274 | J34: 321 | K34: 128 | L34: 258 | M34: 1964 | N34: 3427
E42: MES | F42: (Todas)
B43: INFORMACIÓN INSTITUCIONES EDUCATIVAS | E43: ÁREA DE EDUCACIÓN VIAL | F43: Educación vial en instituciones educativas
B44: MES | C44: (Todas)
B45: ÁREA DE EDUCACIÓN VIAL | C45: Educación vial en instituciones educativas | E45: PÚBLICOS | F45: Suma de TOTAL SEXO
E46: Docentes de secundaria instituciones educativas | F46: 17 | G46: =GETPIVOTDATA("TOTAL PERSONAS INTERVENIDAS",$E$45,"PÚBLICOS","Estudiantes primaria")+GETPIVOTDATA("TOTAL PERSONAS INTERVENIDAS",$E$45,"PÚBLICOS","Estudiantes preescolar") -> #REF!
B47: INSTITUCIONES EDUCATIVAS | C47: Suma de TOTAL SEXO | E47: Estudiantes primaria | F47: 598
B48: COLEGIO COLOMBO BRITÁNICO | C48: 217 | E48: Estudiantes secundaria | F48: 257
B49: Secretaría de Movilidad | C49: 16 | E49: Padres de familia | F49: 84
B50: I.E LA PAZ | C50: 3 | E50: Docentes de primaria instituciones educativas | F50: 65
B51: I.E ALEJANDRO VELEZ BARRIENTOS | C51: 1 | E51: Transportadores escolares | F51: 16
B52: I.E COMERCIAL DE ENVIGADO - SEDE PIO XII | C52: 317 | E52: Rectores de instituciones educativas | F52: 60
B53: I.E LETICIA ARANGO DE AVENDAÑO | C53: 1 | E53: Total general | F53: 1097
B54: I.E JOSE MIGUEL DE LA CALLE | C54: 84
B55: CENTRO EDUCATIVO LA GACELA | C55: 13
B56: I.E DARIO DE BEDOUT | C56: 274
B57: I.E MANUEL URIBE ANGEL - SEDE MARCELIANO VELEZ | C57: 76
B58: Secretaría de Educación | C58: 60
B59: GIMNASIO CANTARES | C59: 22
B60: COLEGIO INTEGRADO LAURELES | C60: 2
B61: CDI TEJIENDO SUEÑOS COMETAS | C61: 2
...

Sheet LISTAS
A1: MES | B1: ÁREAS DE EDUCACIÓN VIAL | C1: PÚBLICOS | D1: TIPO DE INTERVENCIÓN | E1: RESPONSABLE | F1: TIPO DE EVIDENCIA | G1: AÑO | H1: ZONA | I1: DÍA | J1: NOMBRE IE | K1: GEOREFERENCIACIÓN | L1: ZONA | M1: BARRIO
A2: ENE | B2: Centro de Educación Vial | C2: Administrativos instituciones educativas | D2: Acciones por la vida para motociclistas ANSV | E2: Daniel Ríos | F2: Listado de asistencia y fotografías | G2: 2022 | H2: N.A. | I2: 1 | J2: UNIDAD EDUCATIVA SAN MARCOS | K2: 6.176335, -75.586429 | L2: Zona 2 | M2: San Marcos
A3: FEB | B3: Educación vial en empresas | C3: Agentes de Tránsito | D3: Actividad experiencial en educaciòn vial | E3: Jairo Gaviria | F3: Evaluación y listado de asistencia | G3: 2023 | H3: Zona 1 | I3: 2 | J3: LICEO FRANCISCO RESTREPO MOLINA | K3: 6.170484, -75.585466 | L3: Zona 9 | M3: Centro
A4: MAR | B4: Educación vial en instituciones educativas | C4: Auxiliares de tránsito | D4: Atención a padres de familia patrulleros nuevos | E4: Juan Carlos Caicedo | F4: Fotografías | H4: Zona 2 | I4: 3 | J4: LICEO FRANCES | K4: 6.135196, -75.527939 | L4: Zona 12 | M4: Vereda Las Palmas
A5: ABR | B5: Experiencias ciudadanas en movilidad sostenible y segura | C5: Ciclistas | D5: Campaña en vía | E5: Yuliana Ramirez | F5: Certificado de participación | H5: Zona 3 | I5: 4 | J5: I.E SAN VICENTE DE PAUL - SEDE RURAL LA MORENA | K5: 6.167355, -75.565197 | L5: Zona 4 | M5: Loma del Atravesado
A6: MAY | B6: Patrulla de Tránsito | C6: Colaboradores de las diferentes dependencias de la Alcaldía | D6: Ciclopaseo | E6: Felipe Quintero | F6: Acta de reunión y fotografía | H6: Zona 4 | I6: 5 | J6: I.E SAN VICENTE DE PAUL | K6: 6.166862, -75.578916 | L6: Zona 5 | M6: La Pradera
A7: JUN | B7: Plan de formación interno | C7: Conductores de transporte público (buses) | D7: Conversatorio en Movilidad Segura | F7: Video de formación virtual | H7: Zona 5 | I7: 6 | J7: I.E MARTIN EDUARDO RIOS - SEDE LA CRUZ DEL PORVENIR | K7: 6.189958, -75.503116 | L7: Zona 13 | M7: Vereda Perico
A8: JUL | B8: Educación vial para personas mayores | C8: Conductores de transporte público (taxis) | D8: Convocatoria nuevos patrulleros | F8: Reunión virtual | H8: Zona 6 | I8: 7 | J8: I.E MARTIN EDUARDO RIOS | K8: 6.186791, -75.490075 | L8: Zona 13 | M8: Vereda Pantanillo
A9: AGO | B9: Representación en Comités del municipio | C9: Conductores en general | D9: Diálogos de movilidad segura y sostenible | F9: Fotografías e informe de entidad | H9: Zona 7 | I9: 8 | J9: I.E MARIA POUSSSEPIN | K9: 6.171157, -75.577011 | L9: Zona 3 | M9: Uribe Ángel
A10: SEP | B10: Acciones Por La Vida - ANSV | C10: Conductores sancionados por embriaguez | D10: Enviciescuela. Actividad experiencial en bicicleta | H10: Zona 8 | I10: 9 | J10: I.E LAS PALMAS | K10: 6.151222, -75.533765 | L10: Zona 12 | M10: Vereda Las Palmas
A11: OCT | C11: Docentes de primaria instituciones educativas | D11: Evento de ciudad con motociclistas que practican stunt | H11: Zona 9 | I11: 10 | J11: I.E LA PAZ - SEDE JHON F. KENNEDY | K11: 6.165060, -75.590946 | L11: Zona 7 | M11: El Dorado
A12: NOV | C12: Docentes de secundaria instituciones educativas | D12: Formaciòn de Patrulla de Trànsito | H12: Zona 10 | I12: 11 | J12: I.E LA PAZ - SEDE EL TRIANON | K12: 6.157702, -75.591316 | L12: Zona 7 | M12: El Trianón
A13: DIC | C13: Empleados de empresas comerciales y de servicios del municipio | D13: Formación en funciones de auxiliar de tránsito | H13: Zona 11 | I13: 12 | J13: I.E LA PAZ | K13: 6.162272, -75.594035 | L13: Zona 7 | M13: La Paz
C14: Empleados de empresas contratistas de obras | D14: Formación para el fortalecimiento de conocimientos, hábitos y comportamientos seguros | H14: Zona 12 | I14: 13 | J14: I.E JOSE MIGUEL DE LA CALLE | K14: 6.172741, -75.581248 | L14: Zona 9 | M14: Barrio Obrero
C15: Empleados de empresas de transporte del municipio | D15: Formación para el fortalecimiento de conocimientos, hábitos y comportamientos seguros | H15: Zona 13 | I15: 14 | J15: I.E JOSE MANUEL RESTREPO VELEZ - SEDE FERNANDO GONZALEZ | K15: 6.167664, -75.586311 | L15: Zona 9 | M15: Centro
C16: Equipo de educación vial | D16: Formación virtual en movilidad segura y sostenible | H16: General | I16: 15 | J16: I.E JOSE MANUEL RESTREPO VELEZ | K16: 6.171594, -75.591214 | L16: Zona 8 | M16: Alcalá
C17: Estudiantes desde preescolar hasta segundo | D17: Inducción PESV servidores de la Alcaldía | I17: 16 | J17: I.E NORMAL SUPERIOR DE ENVIGADO | K17: 6.167036, -75.581651 | L17: Zona 9 | M17: Barrio Mesa
C18: Estudiantes preescolar | D18: Motodestrezas. Orientación práctica sobre habilidades y destrezas en motocicleta | F18: Zona 9 | I18: 17 | J18: I.E EL SALADO | K18: 6.153244, -75.577675 | L18: Zona 6 | M18: El Salado
C19: Estudiantes primaria | D19: Ofrecimiento de servicios de educación vial | I19: 18 | J19: I.E DARIO DE BEDOUT | K19: 6.167951, -75.578449 | L19: Zona 5 | M19: La Inmaculada
C20: Estudiantes secundaria | D20: Orientación y seguimiento a labor comunitaria | I20: 19 | J20: I.E COMERCIAL DE ENVIGADO - SEDE SAN RAFAEL | K20: 6.157436, -75.583077 | L20: Zona 6 | M20: San Rafael
C21: Estudiantes servicio social del estudiantado | D21: Orientación y seguimiento a labor comunitaria | I21: 20 | J21: I.E COMERCIAL DE ENVIGADO - SEDE PIO XII | K21: 6.165319, -75.581362 | L21: Zona 9 | M21: Barrio Mesa
C22: Estudiantes universitarios | D22: Orientación y seguimiento al Plan de Movilidad Escolar | I22: 21 | J22: I.E COMERCIAL DE ENVIGADO | K22: 6.153470, -75.584819 | L22: Zona 6 | M22: San Rafael
